Workbook

Sheet Cover Page
B2: SUPRA SAEINDIA Cost Report
B5: University: | E5: Ajeenkya DY Patil University
B7: Team Name: | E7: Javitron
B9: Car Number:
B11: Season / Year: | E11: 2025-26
B13: Vehicle Class: | E13: Formula Student / SUPRA
B15: Report Date: | E15: 2026-04-21

Sheet Penalty Calculations
B2: Penalty Calculations
B5: Method A: Direct Penalty
B6: Category | C6: Points per Item | D6: Count | E6: Total Points
B7: Missing / Inaccurate Material | C7: 1 | D7: =0 | E7: =C7*D7
B8: Missing / Inaccurate Process | C8: 1 | D8: =0 | E8: =C8*D8
B9: Missing / Inaccurate Fastener | C9: 1 | D9: =0 | E9: =C9*D9
B10: Missing / Inaccurate Part | C10: 3 | D10: =0 | E10: =C10*D10
B11: Missing / Inaccurate Assembly | C11: 5 | D11: =0 | E11: =C11*D11
B12: Method A Total: | E12: =SUM(E7:E11)
B14: Method B: Cost Penalty
B15: Correct Cost (₹) | C15: Your Cost (₹) | D15: Difference | E15: Penalty (2 × Diff)
B16: =0 | C16: =0 | D16: =B16-C16 | E16: =2*D16

Sheet Table of Contents
B2: Table of Contents
B5: Sheet Name | C5: Description
B7: Cover Page | C7: Team information and report details
B8: Table of Contents | C8: Navigation
B9: Cost Summary | C9: Overall cost breakdown
B10: BOM | C10: Bill of Materials
B11: BR - Brakes | C11: Brakes commodity details
B12: EN - Engine & Drivetrain | C12: Engine & Drivetrain commodity details
B13: FR - Frame & Body | C13: Frame & Body commodity details
B14: EL - Electrical | C14: Electrical commodity details
B15: MS - Misc | C15: Misc commodity details
B16: ST - Steering | C16: Steering commodity details
B17: SU - Suspension | C17: Suspension commodity details
B18: WT - Wheels | C18: Wheels commodity details

Sheet Cost Summary
B2: Cost Summary
B5: Commodity | C5: Code | D5: Total Cost (₹)
B6: Brakes | C6: BR | D6: ='BR - Brakes'!I9
B7: Engine & Drivetrain | C7: EN | D7: ='EN - Engine & Drivetrain'!I9
B8: Frame & Body | C8: FR | D8: ='FR - Frame & Body'!I9
B9: Electrical | C9: EL | D9: ='EL - Electrical'!I9
B10: Misc | C10: MS | D10: ='MS - Misc'!I9
B11: Steering | C11: ST | D11: ='ST - Steering'!I9
B12: Suspension | C12: SU | D12: ='SU - Suspension'!I9
B13: Wheels | C13: WT | D13: ='WT - Wheels'!I9
B14: GRAND TOTAL | D14: =SUM(D6:D15)

Sheet BOM
B2: Bill of Materials
B5: Part Number | C5: Part Name | D5: Assembly | E5: Commodity | F5: Make/Buy | G5: Quantity | H5: Unit Cost | I5: Extended Cost
I6: =H6*G6
I7: =H7*G7
I8: =H8*G8
I9: =H9*G9
I10: =H10*G10
I11: =H11*G11
I12: =H12*G12
I13: =H13*G13
I14: =H14*G14
I15: =H15*G15
I16: =H16*G16
I17: =H17*G17
... I55: =H55*G55

Sheet BR - Brakes
B1: University: | C1: Ajeenkya DY Patil University
B2: Team Name: | C2: Javitron
B3: System: | C3: Brakes
B4: Assembly:
B5: P/N Base: | C5: BR-XX-001
B6: Suffix:
B7: Details:
B9: Car #: | D9: Asm Cost: | E9: =0 | F9: Qty: | G9: 1 | H9: Extended Cost: | I9: =E*G
F10: =D10*E10
B11: Parts | F11: =D11*E11
B12: ItemOrder | C12: Part | D12: Part Cost | E12: Quantity | F12: =D12*E12
B13: 1 | F13: =D13*E13
B14: 2 | F14: =D14*E14
B15: 3 | F15: =D15*E15
B16: 4 | F16: =D16*E16
B17: 5 | F17: =D17*E17
B18: 6 | F18: =D18*E18
B19: 7 | F19: =D19*E19
B20: 8
B21: 9
B22: 10 | O22: =D22*M22
O23: =D23*M23
B24: Materials | O24: =D24*M24
B25: ItemOrder | C25: Material | D25: Use | E25: UnitCost | F25: Unit | G25: Size1 | H25: Unit1 | I25: Size2 | J25: Unit2 | K25: Area | L25: Length | M25: Density | N25: Quantity | O25: =D25*M25
B26: 1 | O26: =D26*M26
B27: 2 | O27: =D27*M27
B28: 3 | O28: =D28*M28
B29: 4 | O29: =D29*M29
B30: 5 | O30: =D30*M30
B31: 6 | O31: =D31*M31
B32: 7
B33: 8
B34: 9 | J34: =D34*F34*H34
B35: 10 | J35: =D35*F35*H35
J36: =D36*F36*H36
B37: Processes | J37: =D37*F37*H37
B38: ItemOrder | C38: Process | D38: Use | E38: UnitCost | F38: Unit | G38: Quantity | H38: Multiplier | I38: Mult. Val. | J38: =D38*F38*H38
B39: 1 | J39: =D39*F39*H39
B40: 2 | J40: =D40*F40*H40
B41: 3 | J41: =D41*F41*H41
...

Sheet EN - Engine & Drivetrain
B1: University: | C1: Ajeenkya DY Patil University
B2: Team Name: | C2: Javitron
B3: System: | C3: Engine & Drivetrain
B4: Assembly:
B5: P/N Base: | C5: EN-XX-001
B6: Suffix:
B7: Details:
B9: Car #: | D9: Asm Cost: | E9: =0 | F9: Qty: | G9: 1 | H9: Extended Cost: | I9: =E*G
F10: =D10*E10
B11: Parts | F11: =D11*E11
B12: ItemOrder | C12: Part | D12: Part Cost | E12: Quantity | F12: =D12*E12
B13: 1 | F13: =D13*E13
B14: 2 | F14: =D14*E14
B15: 3 | F15: =D15*E15
B16: 4 | F16: =D16*E16
B17: 5 | F17: =D17*E17
B18: 6 | F18: =D18*E18
B19: 7 | F19: =D19*E19
B20: 8
B21: 9
B22: 10 | O22: =D22*M22
O23: =D23*M23
B24: Materials | O24: =D24*M24
B25: ItemOrder | C25: Material | D25: Use | E25: UnitCost | F25: Unit | G25: Size1 | H25: Unit1 | I25: Size2 | J25: Unit2 | K25: Area | L25: Length | M25: Density | N25: Quantity | O25: =D25*M25
B26: 1 | O26: =D26*M26
B27: 2 | O27: =D27*M27
B28: 3 | O28: =D28*M28
B29: 4 | O29: =D29*M29
B30: 5 | O30: =D30*M30
B31: 6 | O31: =D31*M31
B32: 7
B33: 8
B34: 9 | J34: =D34*F34*H34
B35: 10 | J35: =D35*F35*H35
J36: =D36*F36*H36
B37: Processes | J37: =D37*F37*H37
B38: ItemOrder | C38: Process | D38: Use | E38: UnitCost | F38: Unit | G38: Quantity | H38: Multiplier | I38: Mult. Val. | J38: =D38*F38*H38
B39: 1 | J39: =D39*F39*H39
B40: 2 | J40: =D40*F40*H40
B41: 3 | J41: =D41*F41*H41
...

Sheet FR - Frame & Body
B1: University: | C1: Ajeenkya DY Patil University
B2: Team Name: | C2: Javitron
B3: System: | C3: Frame & Body
B4: Assembly:
B5: P/N Base: | C5: FR-XX-001
B6: Suffix:
B7: Details:
B9: Car #: | D9: Asm Cost: | E9: =0 | F9: Qty: | G9: 1 | H9: Extended Cost: | I9: =E*G
F10: =D10*E10
B11: Parts | F11: =D11*E11
B12: ItemOrder | C12: Part | D12: Part Cost | E12: Quantity | F12: =D12*E12
B13: 1 | F13: =D13*E13
B14: 2 | F14: =D14*E14
B15: 3 | F15: =D15*E15
B16: 4 | F16: =D16*E16
B17: 5 | F17: =D17*E17
B18: 6 | F18: =D18*E18
B19: 7 | F19: =D19*E19
B20: 8
B21: 9
B22: 10 | O22: =D22*M22
O23: =D23*M23
B24: Materials | O24: =D24*M24
B25: ItemOrder | C25: Material | D25: Use | E25: UnitCost | F25: Unit | G25: Size1 | H25: Unit1 | I25: Size2 | J25: Unit2 | K25: Area | L25: Length | M25: Density | N25: Quantity | O25: =D25*M25
B26: 1 | O26: =D26*M26
B27: 2 | O27: =D27*M27
B28: 3 | O28: =D28*M28
B29: 4 | O29: =D29*M29
B30: 5 | O30: =D30*M30
B31: 6 | O31: =D31*M31
B32: 7
B33: 8
B34: 9 | J34: =D34*F34*H34
B35: 10 | J35: =D35*F35*H35
J36: =D36*F36*H36
B37: Processes | J37: =D37*F37*H37
B38: ItemOrder | C38: Process | D38: Use | E38: UnitCost | F38: Unit | G38: Quantity | H38: Multiplier | I38: Mult. Val. | J38: =D38*F38*H38
B39: 1 | J39: =D39*F39*H39
B40: 2 | J40: =D40*F40*H40
B41: 3 | J41: =D41*F41*H41
...

Sheet EL - Electrical
B1: University: | C1: Ajeenkya DY Patil University
B2: Team Name: | C2: Javitron
B3: System: | C3: Electrical
B4: Assembly:
B5: P/N Base: | C5: EL-XX-001
B6: Suffix:
B7: Details:
B9: Car #: | D9: Asm Cost: | E9: =0 | F9: Qty: | G9: 1 | H9: Extended Cost: | I9: =E*G
F10: =D10*E10
B11: Parts | F11: =D11*E11
B12: ItemOrder | C12: Part | D12: Part Cost | E12: Quantity | F12: =D12*E12
B13: 1 | F13: =D13*E13
B14: 2 | F14: =D14*E14
B15: 3 | F15: =D15*E15
B16: 4 | F16: =D16*E16
B17: 5 | F17: =D17*E17
B18: 6 | F18: =D18*E18
B19: 7 | F19: =D19*E19
B20: 8
B21: 9
B22: 10 | O22: =D22*M22
O23: =D23*M23
B24: Materials | O24: =D24*M24
B25: ItemOrder | C25: Material | D25: Use | E25: UnitCost | F25: Unit | G25: Size1 | H25: Unit1 | I25: Size2 | J25: Unit2 | K25: Area | L25: Length | M25: Density | N25: Quantity | O25: =D25*M25
B26: 1 | O26: =D26*M26
B27: 2 | O27: =D27*M27
B28: 3 | O28: =D28*M28
B29: 4 | O29: =D29*M29
B30: 5 | O30: =D30*M30
B31: 6 | O31: =D31*M31
B32: 7
B33: 8
B34: 9 | J34: =D34*F34*H34
B35: 10 | J35: =D35*F35*H35
J36: =D36*F36*H36
B37: Processes | J37: =D37*F37*H37
B38: ItemOrder | C38: Process | D38: Use | E38: UnitCost | F38: Unit | G38: Quantity | H38: Multiplier | I38: Mult. Val. | J38: =D38*F38*H38
B39: 1 | J39: =D39*F39*H39
B40: 2 | J40: =D40*F40*H40
B41: 3 | J41: =D41*F41*H41
...

Sheet MS - Misc
B1: University: | C1: Ajeenkya DY Patil University
B2: Team Name: | C2: Javitron
B3: System: | C3: Misc
B4: Assembly:
B5: P/N Base: | C5: MS-XX-001
B6: Suffix:
B7: Details:
B9: Car #: | D9: Asm Cost: | E9: =0 | F9: Qty: | G9: 1 | H9: Extended Cost: | I9: =E*G
F10: =D10*E10
B11: Parts | F11: =D11*E11
B12: ItemOrder | C12: Part | D12: Part Cost | E12: Quantity | F12: =D12*E12
B13: 1 | F13: =D13*E13
B14: 2 | F14: =D14*E14
B15: 3 | F15: =D15*E15
B16: 4 | F16: =D16*E16
B17: 5 | F17: =D17*E17
B18: 6 | F18: =D18*E18
B19: 7 | F19: =D19*E19
B20: 8
B21: 9
B22: 10 | O22: =D22*M22
O23: =D23*M23
B24: Materials | O24: =D24*M24
B25: ItemOrder | C25: Material | D25: Use | E25: UnitCost | F25: Unit | G25: Size1 | H25: Unit1 | I25: Size2 | J25: Unit2 | K25: Area | L25: Length | M25: Density | N25: Quantity | O25: =D25*M25
B26: 1 | O26: =D26*M26
B27: 2 | O27: =D27*M27
B28: 3 | O28: =D28*M28
B29: 4 | O29: =D29*M29
B30: 5 | O30: =D30*M30
B31: 6 | O31: =D31*M31
B32: 7
B33: 8
B34: 9 | J34: =D34*F34*H34
B35: 10 | J35: =D35*F35*H35
J36: =D36*F36*H36
B37: Processes | J37: =D37*F37*H37
B38: ItemOrder | C38: Process | D38: Use | E38: UnitCost | F38: Unit | G38: Quantity | H38: Multiplier | I38: Mult. Val. | J38: =D38*F38*H38
B39: 1 | J39: =D39*F39*H39
B40: 2 | J40: =D40*F40*H40
B41: 3 | J41: =D41*F41*H41
...

Sheet ST - Steering
B1: University: | C1: Ajeenkya DY Patil University
B2: Team Name: | C2: Javitron
B3: System: | C3: Steering
B4: Assembly:
B5: P/N Base: | C5: ST-XX-001
B6: Suffix:
B7: Details:
B9: Car #: | D9: Asm Cost: | E9: =0 | F9: Qty: | G9: 1 | H9: Extended Cost: | I9: =E*G
F10: =D10*E10
B11: Parts | F11: =D11*E11
B12: ItemOrder | C12: Part | D12: Part Cost | E12: Quantity | F12: =D12*E12
B13: 1 | F13: =D13*E13
B14: 2 | F14: =D14*E14
B15: 3 | F15: =D15*E15
B16: 4 | F16: =D16*E16
B17: 5 | F17: =D17*E17
B18: 6 | F18: =D18*E18
B19: 7 | F19: =D19*E19
B20: 8
B21: 9
B22: 10 | O22: =D22*M22
O23: =D23*M23
B24: Materials | O24: =D24*M24
B25: ItemOrder | C25: Material | D25: Use | E25: UnitCost | F25: Unit | G25: Size1 | H25: Unit1 | I25: Size2 | J25: Unit2 | K25: Area | L25: Length | M25: Density | N25: Quantity | O25: =D25*M25
B26: 1 | O26: =D26*M26
B27: 2 | O27: =D27*M27
B28: 3 | O28: =D28*M28
B29: 4 | O29: =D29*M29
B30: 5 | O30: =D30*M30
B31: 6 | O31: =D31*M31
B32: 7
B33: 8
B34: 9 | J34: =D34*F34*H34
B35: 10 | J35: =D35*F35*H35
J36: =D36*F36*H36
B37: Processes | J37: =D37*F37*H37
B38: ItemOrder | C38: Process | D38: Use | E38: UnitCost | F38: Unit | G38: Quantity | H38: Multiplier | I38: Mult. Val. | J38: =D38*F38*H38
B39: 1 | J39: =D39*F39*H39
B40: 2 | J40: =D40*F40*H40
B41: 3 | J41: =D41*F41*H41
...

Sheet SU - Suspension
B1: University: | C1: Ajeenkya DY Patil University
B2: Team Name: | C2: Javitron
B3: System: | C3: Suspension
B4: Assembly:
B5: P/N Base: | C5: SU-XX-001
B6: Suffix:
B7: Details:
B9: Car #: | D9: Asm Cost: | E9: =0 | F9: Qty: | G9: 1 | H9: Extended Cost: | I9: =E*G
F10: =D10*E10
B11: Parts | F11: =D11*E11
B12: ItemOrder | C12: Part | D12: Part Cost | E12: Quantity | F12: =D12*E12
B13: 1 | F13: =D13*E13
B14: 2 | F14: =D14*E14
B15: 3 | F15: =D15*E15
B16: 4 | F16: =D16*E16
B17: 5 | F17: =D17*E17
B18: 6 | F18: =D18*E18
B19: 7 | F19: =D19*E19
B20: 8
B21: 9
B22: 10 | O22: =D22*M22
O23: =D23*M23
B24: Materials | O24: =D24*M24
B25: ItemOrder | C25: Material | D25: Use | E25: UnitCost | F25: Unit | G25: Size1 | H25: Unit1 | I25: Size2 | J25: Unit2 | K25: Area | L25: Length | M25: Density | N25: Quantity | O25: =D25*M25
B26: 1 | O26: =D26*M26
B27: 2 | O27: =D27*M27
B28: 3 | O28: =D28*M28
B29: 4 | O29: =D29*M29
B30: 5 | O30: =D30*M30
B31: 6 | O31: =D31*M31
B32: 7
B33: 8
B34: 9 | J34: =D34*F34*H34
B35: 10 | J35: =D35*F35*H35
J36: =D36*F36*H36
B37: Processes | J37: =D37*F37*H37
B38: ItemOrder | C38: Process | D38: Use | E38: UnitCost | F38: Unit | G38: Quantity | H38: Multiplier | I38: Mult. Val. | J38: =D38*F38*H38
B39: 1 | J39: =D39*F39*H39
B40: 2 | J40: =D40*F40*H40
B41: 3 | J41: =D41*F41*H41
...

Sheet WT - Wheels
B1: University: | C1: Ajeenkya DY Patil University
B2: Team Name: | C2: Javitron
B3: System: | C3: Wheels
B4: Assembly:
B5: P/N Base: | C5: WT-XX-001
B6: Suffix:
B7: Details:
B9: Car #: | D9: Asm Cost: | E9: =0 | F9: Qty: | G9: 1 | H9: Extended Cost: | I9: =E*G
F10: =D10*E10
B11: Parts | F11: =D11*E11
B12: ItemOrder | C12: Part | D12: Part Cost | E12: Quantity | F12: =D12*E12
B13: 1 | F13: =D13*E13
B14: 2 | F14: =D14*E14
B15: 3 | F15: =D15*E15
B16: 4 | F16: =D16*E16
B17: 5 | F17: =D17*E17
B18: 6 | F18: =D18*E18
B19: 7 | F19: =D19*E19
B20: 8
B21: 9
B22: 10 | O22: =D22*M22
O23: =D23*M23
B24: Materials | O24: =D24*M24
B25: ItemOrder | C25: Material | D25: Use | E25: UnitCost | F25: Unit | G25: Size1 | H25: Unit1 | I25: Size2 | J25: Unit2 | K25: Area | L25: Length | M25: Density | N25: Quantity | O25: =D25*M25
B26: 1 | O26: =D26*M26
B27: 2 | O27: =D27*M27
B28: 3 | O28: =D28*M28
B29: 4 | O29: =D29*M29
B30: 5 | O30: =D30*M30
B31: 6 | O31: =D31*M31
B32: 7
B33: 8
B34: 9 | J34: =D34*F34*H34
B35: 10 | J35: =D35*F35*H35
J36: =D36*F36*H36
B37: Processes | J37: =D37*F37*H37
B38: ItemOrder | C38: Process | D38: Use | E38: UnitCost | F38: Unit | G38: Quantity | H38: Multiplier | I38: Mult. Val. | J38: =D38*F38*H38
B39: 1 | J39: =D39*F39*H39
B40: 2 | J40: =D40*F40*H40
B41: 3 | J41: =D41*F41*H41
...
